Workbook

Sheet 理论测算 
A1: 2026-2030年盈利测算表-测算框架
A2: 项目 | B2: 2024年 | C2: 2025年 | E2: 2026年 | G2: 2027年 | I2: 2028年 | K2: 2029年 | M2: 2030年 | O2: 十五五 平均增量 | P2: 十五五 累计增量 | Q2: 十五五 复合增速
C3: 余额 | D3: 年增 | E3: 余额 | F3: 年增 | G3: 余额 | H3: 年增 | I3: 余额 | J3: 年增 | K3: 余额 | L3: 年增 | M3: 余额 | N3: 年增
A4: 一、盈利结果
A5: （一）并表口径
A6: 归母净利润 | C6: 706.18 | D6: 20.42 | E6: =D33 -> 767.86252 | F6: =E6-C6 -> 61.682516 | G6: =E33 -> 854.5966 | H6: =G6-E6 -> 86.734079 | I6: =F33 -> 943.23317 | J6: =I6-G6 -> 88.636571 | K6: =G33 -> 1049.0656 | L6: =K6-I6 -> 105.8324 | M6: =H33 -> 1175.2513 | N6: =M6-K6 -> 126.1857 | O6: =P6/5 -> 93.814252 | P6: =M6-C6 -> 469.07126 | Q6: =(M6/C6)^(1/5)-1 -> 0.1072433
A7: 营业净收入 | C7: 2124.75 | D7: -11.71 | E7: =E8+E9 -> 2190.1054 | F7: =E7-C7 -> 65.355413 | G7: =G8+G9 -> 2299.1969 | H7: =G7-E7 -> 109.09149 | I7: =I8+I9 -> 2400.0048 | J7: =I7-G7 -> 100.80785 | K7: =K8+K9 -> 2497.9422 | L7: =K7-I7 -> 97.937396 | M7: =M8+M9 -> 2598.0386 | N7: =M7-K7 -> 100.09648 | O7: =P7/5 -> 94.657726 | P7: =M7-C7 -> 473.28863 | Q7: =(M7/C7)^(1/5)-1 -> 0.041040327
A8: 其中：利息净收入 | C8: 1444.69 | D8: -22.1 | E8: =(C11+E11)/2*E17*E18 -> 1500.0032 | F8: =E8-C8 -> 55.313197 | G8: =(E11+G11)/2*G17*G18 -> 1586.2159 | H8: =G8-E8 -> 86.212747 | I8: =(G11+I11)/2*I17*I18 -> 1667.7633 | J8: =I8-G8 -> 81.547361 | K8: =(I11+K11)/2*K17*K18 -> 1748.3097 | L8: =K8-I8 -> 80.546407 | M8: =(K11+M11)/2*M17*M18 -> 1831.3574 | N8: =M8-K8 -> 83.047718 | O8: =P8/5 -> 77.333486 | P8: =M8-C8 -> 386.66743 | Q8: =(M8/C8)^(1/5)-1 -> 0.04857546
A9: 非利息净收入 | C9: 680.06 | D9: 10.39 | E9: =E19*E8/(1-E19) -> 690.10222 | F9: =E9-C9 -> 10.042216 | G9: =G19*G8/(1-G19) -> 712.98096 | H9: =G9-E9 -> 22.878744 | I9: =I19*I8/(1-I19) -> 732.24145 | J9: =I9-G9 -> 19.260491 | K9: =K19*K8/(1-K19) -> 749.63244 | L9: =K9-I9 -> 17.390989 | M9: =M19*M8/(1-M19) -> 766.6812 | N9: =M9-K9 -> 17.04876 | O9: =P9/5 -> 17.32424 | P9: =M9-C9 -> 86.6212 | Q9: =(M9/C9)^(1/5)-1 -> 0.024267792
A10: 二、一级核心指标
A11: 总资产 | B11: 95327.22 | C11: 101310.28 | D11: 5989.36 | E11: =C11+F11 -> 108000.28 | F11: 6690 | G11: =E11+H11 -> 113200.28 | H11: 5200 | I11: =G11+J11 -> 118600.28 | J11: 5400 | K11: =I11+L11 -> 124200.28 | L11: 5600 | M11: =K11+N11 -> 130000.28 | N11: =5800 -> 5800 | O11: =P11/5 -> 5738 | P11: =M11-C11 -> 28690 | Q11: =(M11/C11)^(1/5)-1 -> 0.05113417
A12: ROE | C12: 0.0939 | D12: =C12-9.79% -> -0.004 | E12: =D46 -> 0.097100174 | F12: =E12-C12 -> 0.003200174 | G12: =E46 -> 0.10142433 | H12: =G12-E12 -> 0.0043241576 | I12: =F46 -> 0.10111302 | J12: =I12-G12 -> -0.00031130948 | K12: =G46 -> 0.10323922 | L12: =K12-I12 -> 0.0021262007 | M12: =H46 -> 0.10650149 | N12: =M12-K12 -> 0.0032622683 | O12: =P12/5 -> 0.0025202982 | P12: =M12-C12 -> 0.012601491
A13: RAROC | C13: 0.0881 | D13: -0.0034 | E13: =D64 -> 0.087525447 | F13: =E13-C13 -> -0.00057455281 | G13: =E64 -> 0.089659256 | H13: =G13-E13 -> 0.0021338091 | I13: =F64 -> 0.092664086 | J13: =I13-G13 -> 0.0030048296 | K13: =G64 -> 0.096843159 | L13: =K13-I13 -> 0.0041790736 | M13: =H64 -> 0.10226377 | N13: =M13-K13 -> 0.0054206079 | O13: =P13/5 -> 0.0028327535 | P13: =M13-C13 -> 0.014163767
A14: 风险加权资产 | C14: 76843.388 | D14: 6156.0257 | E14: =D53 -> 84743.388 | F14: =E14-C14 -> 7900 | G14: =E53 -> 90586.397 | H14: =G14-E14 -> 5843.0085 | I14: =F53 -> 96449.519 | J14: =I14-G14 -> 5863.1221 | K14: =G53 -> 102384.74 | L14: =K14-I14 -> 5935.2183 | M14: =H53 -> 108345.06 | N14: =M14-K14 -> 5960.3227 | O14: =P14/5 -> 6300.3343 | P14: =M14-C14 -> 31501.672 | Q14: =(M14/C14)^(1/5)-1 -> 0.071125902
A15: 核心一级资本充足率 | C15: 0.0948 | D15: -0.0024 | E15: =D54 -> 0.092188918 | F15: =E15-C15 -> -0.002611082 | G15: =E54 -> 0.0959149 | H15: =G15-E15 -> 0.0037259824 | I15: =F54 -> 0.097522797 | J15: =I15-G15 -> 0.0016078964 | K15: =G54 -> 0.099495276 | L15: =K15-I15 -> 0.0019724795 | M15: =H54 -> 0.10195561 | N15: =M15-K15 -> 0.0024603314 | O15: =P15/5 -> 0.0014311215 | P15: =M15-C15 -> 0.0071556077
A16: 三、二级核心指标
A17: 生息资产占比（日均） | C17: 0.9008 | E17: =C17+F17 -> 0.8958 | F17: -0.005 | G17: =E17+H17 -> 0.8908 | H17: -0.005 | I17: =G17+J17 -> 0.8828 | J17: -0.008 | K17: =I17+L17 -> 0.8728 | L17: -0.01 | M17: =K17+N17 -> 0.8628 | N17: -0.01 | O17: =P17/5 -> -0.0076 | P17: =M17-C17 -> -0.038
A18: 净息差 | C18: 0.0163 | D18: -0.0014 | E18: 0.016 | F18: =E18-C18 -> -0.0003 | G18: 0.0161 | H18: =G18-E18 -> 0.0001 | I18: 0.0163 | J18: =I18-G18 -> 0.0002 | K18: 0.0165 | L18: =K18-I18 -> 0.0002 | M18: 0.0167 | N18: =M18-K18 -> 0.0002 | O18: =P18/5 -> 8e-05 | P18: =M18-C18 -> 0.0004
A19: 非息收入占比 | C19: 0.3201 | D19: 0.0067 | E19: =C19+F19 -> 0.3151 | F19: -0.005 | G19: =E19+H19 -> 0.3101 | H19: -0.005 | I19: =G19+J19 -> 0.3051 | J19: -0.005 | K19: =I19+L19 -> 0.3001 | L19: -0.005 | M19: =K19+N19 -> 0.2951 | N19: -0.005 | O19: =P19/5 -> -0.005 | P19: =M19-C19 -> -0.025
A20: 成本收入比 | C20: 0.31607954 | D20: -0.0088 | E20: =C20+F20 -> 0.30997954 | F20: -0.0061 | G20: =E20+H20 -> 0.30497954 | H20: -0.005 | I20: =G20+J20 -> 0.29997954 | J20: -0.005 | K20: =I20+L20 -> 0.29497954 | L20: -0.005 | M20: =K20+N20 -> 0.28997954 | N20: -0.005 | O20: =P20/5 -> -0.00522 | P20: =M20-C20 -> -0.0261
A21: 风险成本率 | C21: 0.2737828 | E21: =L37 -> 0.26117464 | F21: =E21-C21 -> -0.012608155 | G21: =M37 -> 0.24530304 | H21: =G21-E21 -> -0.015871599 | I21: =N37 -> 0.22916621 | J21: =I21-G21 -> -0.016136832 | K21: =O37 -> 0.20737069 | L21: =K21-I21 -> -0.021795518 | M21: =P37 -> 0.18013589 | N21: =M21-K21 -> -0.027234805 | O21: =P21/5 -> -0.018729382 | P21: =M21-C21 -> -0.093646908
A22: 税务成本率 | C22: 0.069255206 | E22: =C22+F22 -> 0.069255206 | F22: 0 | G22: =E22+H22 -> 0.069255206 | H22: 0 | I22: =G22+J22 -> 0.069255206 | J22: 0 | K22: =I22+L22 -> 0.069255206 | L22: 0 | M22: =K22+N22 -> 0.069255206 | N22: 0 | O22: =P22/5 -> 0 | P22: =M22-C22 -> 0
A23: 其他（营业外收支率） | C23: 0.0044193435 | E23: =C23+F23 -> 0.0044193435 | F23: 0 | G23: =E23+H23 -> 0.0044193435 | H23: 0 | I23: =G23+J23 -> 0.0044193435 | J23: 0 | K23: =I23+L23 -> 0.0044193435 | L23: 0 | M23: =K23+N23 -> 0.0044193435 | N23: 0 | O23: =P23/5 -> 0 | P23: =M23-C23 -> 0
A24: 综合风险权重 | C24: =C63 -> 0.75026761 | E24: =D63 -> 0.77199534 | F24: =E24-C24 -> 0.021727722 | G24: =E63 -> 0.79262812 | H24: =G24-E24 -> 0.020632787 | I24: =F63 -> 0.80688293 | J24: =I24-G24 -> 0.014254808 | K24: =G63 -> 0.81892009 | L24: =K24-I24 -> 0.012037156 | M24: =H63 -> 0.82899029 | N24: =M24-K24 -> 0.010070206 | O24: =P24/5 -> 0.015744536 | P24: =M24-C24 -> 0.078722678
A25: 四、权益端
A26: 归母净资产 | C26: 8288.13 | D26: 395.49 | E26: =D49 -> 8752.6256 | F26: =E26-C26 -> 464.49564 | G26: =E49 -> 9874.0248 | H26: =G26-E26 -> 1121.3992 | I26: =F49 -> 10984.107 | J26: =I26-G26 -> 1110.082 | K26: =G49 -> 12056.157 | L26: =K26-I26 -> 1072.0502 | M26: =H49 -> 13206.913 | N26: =M26-K26 -> 1150.7557 | O26: =P26/5 -> 983.75655 | P26: =M26-C26 -> 4918.7828 | Q26: =(M26/C26)^(1/5)-1 -> 0.097662812
A27: 其中：归属母公司普通股股东净资产 | C27: =C48 -> 7238.13 | D27: =D26 -> 395.49 | E27: =D48 -> 7702.6256 | F27: =E27-C27 -> 464.49564 | G27: =E48 -> 8624.0248 | H27: =G27-E27 -> 921.3992 | I27: =F48 -> 9334.1069 | J27: =I27-G27 -> 710.08201 | K27: =G48 -> 10106.157 | L27: =K27-I27 -> 772.05018 | M27: =H48 -> 10956.913 | N27: =M27-K27 -> 850.75573 | O27: =P27/5 -> 743.75655 | P27: =M27-C27 -> 3718.7828 | Q27: =(M27/C27)^(1/5)-1 -> 0.086456556
J29: 规划报告参数
A30: 项目 | B30: 2024年 | C30: 2025年 | D30: 2026年 | E30: 2027年 | F30: 2028年 | G30: 2029年 | H30: 2030年
A31: 总资产 | B31: =B11 -> 95327.22 | C31: =C11 -> 101310.28 | D31: =E11 -> 108000.28 | E31: =G11 -> 113200.28 | F31: =I11 -> 118600.28 | G31: =K11 -> 124200.28 | H31: =M11 -> 130000.28 | J31: 集团净利润 | K31: 714.9 | L31: 809.1 | M31: 890.3 | N31: 979.9 | O31: 1079.3 | P31: 1189.9
A32: 净利润 | C32: =(1-C20-C21-C22-C23)*C7 -> 714.9 | D32: =(1-E20-E21-E22-E23)*E7 -> 777.86252 | E32: =(1-G20-G21-G22-G23)*G7 -> 864.5966 | F32: =(1-I20-I21-I22-I23)*I7 -> 953.23317 | G32: =(1-K20-K21-K22-K23)*K7 -> 1059.0656 | H32: =(1-M20-M21-M22-M23)*M7 -> 1185.2513 | J32: 归母净利润 | K32: 706.2 | L32: 799.2 | M32: 879.5 | N32: 967.9 | O32: 1066.2 | P32: 1175.4
A33: 归母净利润 | C33: =C6 -> 706.18 | D33: =D32-10 -> 767.86252 | E33: =E32-10 -> 854.5966 | F33: =F32-10 -> 943.23317 | G33: =G32-10 -> 1049.0656 | H33: =H32-10 -> 1175.2513 | J33: 总资产 | K33: 101310 | L33: 108662 | M33: 113750 | N33: 118422 | O33: 123191 | P33: 127484
A34: 优先股、永续债分红 | D34: -38.34 | E34: -25.2 | F34: -30 | G34: -39.6 | H34: -46.8 | J34: RWA/总资产 | K34: 0.7585 | L34: 0.7486 | M34: 0.7371 | N34: 0.7249 | O34: 0.7129 | P34: 0.7021
A35: 分红率 | D35: 0.307 | E35: 0.307 | F35: 0.307 | G35: 0.307 | H35: 0.307 | J35: 净息差 | K35: 0.0163 | L35: 0.016 | M35: 0.0161 | N35: 0.0163 | O35: 0.0165 | P35: 0.0167
A36: 现金分红 | D36: =-(C33+D34)*D35 -> -205.02688 | E36: =-(D33+E34)*E35 -> -227.99739 | F36: =-(E33+F34)*F35 -> -253.15115 | G36: =-(F33+G34)*G35 -> -277.41538 | H36: =-(G33+H34)*H35 -> -307.69553 | J36: 信用减值（亿元） | K36: 582 | L36: 572 | M36: 564 | N36: 550 | O36: 518 | P36: 468
A37: 第一次分红 | D37: =D36/2 -> -102.51344 | E37: =E36/2 -> -113.9987 | F37: =F36/2 -> -126.57558 | G37: =G36/2 -> -138.70769 | H37: =H36/2 -> -153.84776 | J37: 风险成本率 | K37: =K36/C7 -> 0.27391458 | L37: =L36/E7 -> 0.26117464 | M37: =M36/G7 -> 0.24530304 | N37: =N36/I7 -> 0.22916621 | O37: =O36/K7 -> 0.20737069 | P37: =P36/M7 -> 0.18013589
A38: 剩余月份 | D38: 6 | E38: 6 | F38: 6 | G38: 6 | H38: 6 | J38: ROE | K38: 0.0939 | L38: 0.092 | M38: 0.093 | N38: 0.096 | O38: 0.099 | P38: 0.1025
A39: 影响1 | D39: =D37*D38/12 -> -51.25672 | E39: =E37*E38/12 -> -56.999348 | F39: =F37*F38/12 -> -63.287789 | G39: =G37*G38/12 -> -69.353845 | H39: =H37*H38/12 -> -76.923882 | J39: RAROC | K39: 0.0881 | L39: 0.093 | M39: 0.098 | N39: 0.105 | O39: 0.113 | P39: 0.122
A40: 第二次分红 | D40: =D37 -> -102.51344 | E40: =E37 -> -113.9987 | F40: =F37 -> -126.57558 | G40: =G37 -> -138.70769 | H40: =H37 -> -153.84776 | J40: 核心一级资本充足率 | K40: 0.0948 | L40: 0.097 | M40: 0.1 | N40: 0.103 | O40: 0.106 | P40: 0.111
A41: 剩余月份 | D41: 1 | E41: 1 | F41: 1 | G41: 1 | H41: 1 | J41: 成本收入比 | K41: 0.3161 | L41: 0.31 | M41: 0.305 | N41: 0.3 | O41: 0.295 | P41: 0.29
...

Sheet 汇总展示表
A1: 三种情景对比情况（V0708)
A2: 项目 | B2: 指标 | C2: 2025实际 | D2: 积极情景
D3: 2026年 | E3: 2027年 | F3: 2028年 | G3: 2029年 | H3: 2030年 | I3: 十五五总增量/累计变化 | J3: 复合增速
A4: 财务结果 | B4: 一、盈利结果
B5: （一）并表口径
B6: 归母净利润 | C6: ='2026-2030年盈利测算表'!L6 -> 706.18 | D6: ='2026-2030年盈利测算表'!N6 -> 757.81904 | E6: ='2026-2030年盈利测算表'!P6 -> 810.60057 | F6: ='2026-2030年盈利测算表'!R6 -> 866.01284 | G6: ='2026-2030年盈利测算表'!T6 -> 927.36198 | H6: ='2026-2030年盈利测算表'!V6 -> 985.20062 | I6: ='2026-2030年盈利测算表'!X6 -> 279.02062 | J6: ='2026-2030年盈利测算表'!Y6 -> 0.06886253
B7: 营业净收入 | C7: ='2026-2030年盈利测算表'!L7 -> 2124.75 | D7: ='2026-2030年盈利测算表'!N7 -> 2219.8843 | E7: ='2026-2030年盈利测算表'!P7 -> 2344.467 | F7: ='2026-2030年盈利测算表'!R7 -> 2461.359 | G7: ='2026-2030年盈利测算表'!T7 -> 2591.0856 | H7: ='2026-2030年盈利测算表'!V7 -> 2707.3909 | I7: ='2026-2030年盈利测算表'!X7 -> 582.64091 | J7: ='2026-2030年盈利测算表'!Y7 -> 0.049659947
B8: 其中：利息净收入 | C8: ='2026-2030年盈利测算表'!L8 -> 1444.69 | D8: ='2026-2030年盈利测算表'!N8 -> 1487.1203 | E8: ='2026-2030年盈利测算表'!P8 -> 1594.5546 | F8: ='2026-2030年盈利测算表'!R8 -> 1671.7017 | G8: ='2026-2030年盈利测算表'!T8 -> 1751.2832 | H8: ='2026-2030年盈利测算表'!V8 -> 1811.7919 | I8: ='2026-2030年盈利测算表'!X8 -> 367.10188 | J8: ='2026-2030年盈利测算表'!Y8 -> 0.046325305
B9: 非利息净收入 | C9: ='2026-2030年盈利测算表'!L9 -> 680.06 | D9: ='2026-2030年盈利测算表'!N9 -> 732.76405 | E9: ='2026-2030年盈利测算表'!P9 -> 749.91237 | F9: ='2026-2030年盈利测算表'!R9 -> 789.65734 | G9: ='2026-2030年盈利测算表'!T9 -> 839.80245 | H9: ='2026-2030年盈利测算表'!V9 -> 895.59903 | I9: ='2026-2030年盈利测算表'!X9 -> 215.53903 | J9: ='2026-2030年盈利测算表'!Y9 -> 0.056606496
B10: （二）本行口径
B11: 净利润 | C11: ='2026-2030年盈利测算表'!L11 -> 647.01 | D11: ='2026-2030年盈利测算表'!N11 -> 685.87278 | E11: ='2026-2030年盈利测算表'!P11 -> 718.39854 | F11: ='2026-2030年盈利测算表'!R11 -> 762.80085 | G11: ='2026-2030年盈利测算表'!T11 -> 811.01314 | H11: ='2026-2030年盈利测算表'!V11 -> 855.33941 | I11: ='2026-2030年盈利测算表'!X11 -> 208.32941 | J11: ='2026-2030年盈利测算表'!Y11 -> 0.057415076
B12: 营业净收入（本行） | C12: ='2026-2030年盈利测算表'!L12 -> 1941.64 | D12: ='2026-2030年盈利测算表'!N12 -> 2027.8379 | E12: ='2026-2030年盈利测算表'!P12 -> 2090.0167 | F12: ='2026-2030年盈利测算表'!R12 -> 2184.245 | G12: ='2026-2030年盈利测算表'!T12 -> 2286.2919 | H12: ='2026-2030年盈利测算表'!V12 -> 2374.435 | I12: ='2026-2030年盈利测算表'!X12 -> 432.79497 | J12: ='2026-2030年盈利测算表'!Y12 -> 0.041066122
B13: 其中：利息净收入 | C13: ='2026-2030年盈利测算表'!L13 -> 1359.33 | D13: ='2026-2030年盈利测算表'!N13 -> 1398.7484 | E13: ='2026-2030年盈利测算表'!P13 -> 1456.7307 | F13: ='2026-2030年盈利测算表'!R13 -> 1520.0171 | G13: ='2026-2030年盈利测算表'!T13 -> 1582.4091 | H13: ='2026-2030年盈利测算表'!V13 -> 1625.5724 | I13: ='2026-2030年盈利测算表'!X13 -> 266.24242 | J13: ='2026-2030年盈利测算表'!Y13 -> 0.036421192
B14: 非利息净收入 | C14: ='2026-2030年盈利测算表'!L14 -> 582.31 | D14: ='2026-2030年盈利测算表'!N14 -> 629.08942 | E14: ='2026-2030年盈利测算表'!P14 -> 633.28595 | F14: ='2026-2030年盈利测算表'!R14 -> 664.22788 | G14: ='2026-2030年盈利测算表'!T14 -> 703.88282 | H14: ='2026-2030年盈利测算表'!V14 -> 748.86255 | I14: ='2026-2030年盈利测算表'!X14 -> 166.55255 | J14: ='2026-2030年盈利测算表'!Y14 -> 0.051597566
B15: 二、一级核心指标（并表）
B16: 总资产 | C16: ='2026-2030年盈利测算表'!L16 -> 101316.58 | D16: ='2026-2030年盈利测算表'!N16 -> 107999.58 | E16: ='2026-2030年盈利测算表'!P16 -> 114699.58 | F16: ='2026-2030年盈利测算表'!R16 -> 119599.58 | G16: ='2026-2030年盈利测算表'!T16 -> 124699.58 | H16: ='2026-2030年盈利测算表'!V16 -> 129999.58 | I16: ='2026-2030年盈利测算表'!X16 -> 28683 | J16: ='2026-2030年盈利测算表'!Y16 -> 0.051119966
B17: ROE | C17: ='2026-2030年盈利测算表'!L17 -> 0.0939 | D17: ='2026-2030年盈利测算表'!N17 -> 0.095294354 | E17: ='2026-2030年盈利测算表'!P17 -> 0.095069286 | F17: ='2026-2030年盈利测算表'!R17 -> 0.0922937 | G17: ='2026-2030年盈利测算表'!T17 -> 0.091916814 | H17: ='2026-2030年盈利测算表'!V17 -> 0.091152488 | I17: ='2026-2030年盈利测算表'!X17 -> -0.0027475118
B18: RAROC | C18: ='2026-2030年盈利测算表'!L18 -> 0.0881 | D18: ='2026-2030年盈利测算表'!N18 -> 0.087980207 | E18: ='2026-2030年盈利测算表'!P18 -> 0.087539869 | F18: ='2026-2030年盈利测算表'!R18 -> 0.087814458 | G18: ='2026-2030年盈利测算表'!T18 -> 0.089743652 | H18: ='2026-2030年盈利测算表'!V18 -> 0.090961541 | I18: ='2026-2030年盈利测算表'!X18 -> 0.0028615414
B19: 核心一级资本充足率 | C19: ='2026-2030年盈利测算表'!L19 -> 0.0948 | D19: ='2026-2030年盈利测算表'!N19 -> 0.095730282 | E19: ='2026-2030年盈利测算表'!P19 -> 0.099696284 | F19: ='2026-2030年盈利测算表'!R19 -> 0.10129985 | G19: ='2026-2030年盈利测算表'!T19 -> 0.10303652 | H19: ='2026-2030年盈利测算表'!V19 -> 0.10472588 | I19: ='2026-2030年盈利测算表'!X19 -> 0.0099258831
B20: 三、二级核心指标（并表）
B21: 生息资产日均 | C21: ='2026-2030年盈利测算表'!L21 -> 88562.26 | D21: ='2026-2030年盈利测算表'!N21 -> 92357.244 | E21: ='2026-2030年盈利测算表'!P21 -> 100806.96 | F21: ='2026-2030年盈利测算表'!R21 -> 106212.59 | G21: ='2026-2030年盈利测算表'!T21 -> 110798.4 | H21: ='2026-2030年盈利测算表'!V21 -> 115610.38 | I21: ='2026-2030年盈利测算表'!X21 -> 27048.122 | J21: ='2026-2030年盈利测算表'!Y21 -> 0.054750232
B22: 生息资产占比（日均） | C22: ='2026-2030年盈利测算表'!L22 -> 0.90073889 | D22: ='2026-2030年盈利测算表'!N22 -> 0.91384354 | E22: ='2026-2030年盈利测算表'!P22 -> 0.91260154 | F22: ='2026-2030年盈利测算表'!R22 -> 0.91416923 | G22: ='2026-2030年盈利测算表'!T22 -> 0.91566453 | H22: ='2026-2030年盈利测算表'!V22 -> 0.91707937 | I22: ='2026-2030年盈利测算表'!X22 -> 0.016340478
B23: 净息差 | C23: ='2026-2030年盈利测算表'!L23 -> 0.016312705 | D23: ='2026-2030年盈利测算表'!N23 -> 0.016101826 | E23: ='2026-2030年盈利测算表'!P23 -> 0.015817902 | F23: ='2026-2030年盈利测算表'!R23 -> 0.015739205 | G23: ='2026-2030年盈利测算表'!T23 -> 0.015806033 | H23: ='2026-2030年盈利测算表'!V23 -> 0.015671533 | I23: ='2026-2030年盈利测算表'!X23 -> -0.00064117211
B24: 非息收入占比 | C24: ='2026-2030年盈利测算表'!L24 -> 0.32006589 | D24: ='2026-2030年盈利测算表'!N24 -> 0.3300911 | E24: ='2026-2030年盈利测算表'!P24 -> 0.31986476 | F24: ='2026-2030年盈利测算表'!R24 -> 0.32082168 | G24: ='2026-2030年盈利测算表'!T24 -> 0.32411219 | H24: ='2026-2030年盈利测算表'!V24 -> 0.33079783 | I24: ='2026-2030年盈利测算表'!X24 -> 0.010731936
B25: 成本收入比 | C25: ='2026-2030年盈利测算表'!L25 -> 0.31607954 | D25: ='2026-2030年盈利测算表'!N25 -> 0.31607954 | E25: ='2026-2030年盈利测算表'!P25 -> 0.31557954 | F25: ='2026-2030年盈利测算表'!R25 -> 0.31507954 | G25: ='2026-2030年盈利测算表'!T25 -> 0.31457954 | H25: ='2026-2030年盈利测算表'!V25 -> 0.31407954 | I25: ='2026-2030年盈利测算表'!X25 -> -0.002
B26: 风险成本率 | C26: ='2026-2030年盈利测算表'!L26 -> 0.2737828 | D26: ='2026-2030年盈利测算表'!N26 -> 0.2687828 | E26: ='2026-2030年盈利测算表'!P26 -> 0.2637828 | F26: ='2026-2030年盈利测算表'!R26 -> 0.2587828 | G26: ='2026-2030年盈利测算表'!T26 -> 0.2537828 | H26: ='2026-2030年盈利测算表'!V26 -> 0.2487828 | I26: ='2026-2030年盈利测算表'!X26 -> -0.025
B27: 税务成本率 | C27: ='2026-2030年盈利测算表'!L27 -> 0.069255206 | D27: ='2026-2030年盈利测算表'!N27 -> 0.069255206 | E27: ='2026-2030年盈利测算表'!P27 -> 0.069255206 | F27: ='2026-2030年盈利测算表'!R27 -> 0.069255206 | G27: ='2026-2030年盈利测算表'!T27 -> 0.069255206 | H27: ='2026-2030年盈利测算表'!V27 -> 0.069255206 | I27: ='2026-2030年盈利测算表'!X27 -> 0
B28: 综合风险权重 | C28: ='2026-2030年盈利测算表'!L28 -> 0.75026761 | D28: ='2026-2030年盈利测算表'!N28 -> 0.75809131 | E28: ='2026-2030年盈利测算表'!P28 -> 0.7653228 | F28: ='2026-2030年盈利测算表'!R28 -> 0.77412488 | G28: ='2026-2030年盈利测算表'!T28 -> 0.77735417 | H28: ='2026-2030年盈利测算表'!V28 -> 0.78102084 | I28: ='2026-2030年盈利测算表'!X28 -> 0.030753229
B29: 其中：本行 | C29: =资本!L93 -> 0.73882582 | D29: =资本!M93 -> 0.73527171 | E29: =资本!N93 -> 0.73753298 | F29: =资本!O93 -> 0.74437169 | G29: =资本!P93 -> 0.74742416 | H29: =资本!Q93 -> 0.75164085 | I29: =H29-C29 -> 0.012815038
B30: 子公司 | C30: =子公司!L121 -> 1.0143933 | D30: =子公司!N121 -> 1.0991803 | E30: =子公司!P121 -> 1.0730382 | F30: =子公司!R121 -> 1.0663262 | G30: =子公司!T121 -> 1.0553433 | H30: =子公司!V121 -> 1.0337519 | I30: =H30-C30 -> 0.019358611
B31: 本行规模占比 | C31: ='2026-2030年盈利测算表'!L199 -> 0.93938183 | D31: ='2026-2030年盈利测算表'!N199 -> 0.93874939 | E31: ='2026-2030年盈利测算表'!P199 -> 0.91930027 | F31: ='2026-2030年盈利测算表'!R199 -> 0.91531591 | G31: ='2026-2030年盈利测算表'!T199 -> 0.91077129 | H31: ='2026-2030年盈利测算表'!V199 -> 0.90536625 | I31: =H31-C31 -> -0.034015574
B32: 四、其他指标（本行）
B33: 净息差 | C33: ='2026-2030年盈利测算表'!L30 -> 0.016376089 | D33: ='2026-2030年盈利测算表'!N30 -> 0.016226546 | E33: ='2026-2030年盈利测算表'!P30 -> 0.015620824 | F33: ='2026-2030年盈利测算表'!R30 -> 0.015656156 | G33: ='2026-2030年盈利测算表'!T30 -> 0.016 | H33: ='2026-2030年盈利测算表'!V30 -> 0.015529954 | I33: ='2026-2030年盈利测算表'!X30 -> -0.00084613518
B34: 生息资产日均 | C34: ='2026-2030年盈利测算表'!L53 -> 83007 | D34: ='2026-2030年盈利测算表'!N53 -> 86201.245 | E34: ='2026-2030年盈利测算表'!P53 -> 93255.692 | F34: ='2026-2030年盈利测算表'!R53 -> 97087.509 | G34: ='2026-2030年盈利测算表'!T53 -> 100835.36 | H34: ='2026-2030年盈利测算表'!V53 -> 104673.36 | I34: ='2026-2030年盈利测算表'!X53 -> 21666.36 | J34: ='2026-2030年盈利测算表'!Y53 -> 0.047476503
B35: 信贷资产占比（一般贷款/总资产，时点，人民币） | C35: ='2026-2030年盈利测算表'!L32 -> 0.56379388 | D35: ='2026-2030年盈利测算表'!N32 -> 0.56215249 | E35: ='2026-2030年盈利测算表'!P32 -> 0.56811999 | F35: ='2026-2030年盈利测算表'!R32 -> 0.57145845 | G35: ='2026-2030年盈利测算表'!T32 -> 0.57188144 | H35: ='2026-2030年盈利测算表'!V32 -> 0.56995208 | I35: ='2026-2030年盈利测算表'!X32 -> 0.0061581994
B36: 自营存款占比（时点，人民币） | C36: ='2026-2030年盈利测算表'!L33 -> 0.66132456 | D36: ='2026-2030年盈利测算表'!N33 -> 0.65691877 | E36: ='2026-2030年盈利测算表'!P33 -> 0.6767207 | F36: ='2026-2030年盈利测算表'!R33 -> 0.69682107 | G36: ='2026-2030年盈利测算表'!T33 -> 0.7168917 | H36: ='2026-2030年盈利测算表'!V33 -> 0.73792925 | I36: ='2026-2030年盈利测算表'!X33 -> 0.076604693
B37: 零售存款占比（日均） | C37: ='2026-2030年盈利测算表'!L34 -> 0.28711748 | D37: ='2026-2030年盈利测算表'!N34 -> 0.29448384 | E37: ='2026-2030年盈利测算表'!P34 -> 0.30511638 | F37: ='2026-2030年盈利测算表'!R34 -> 0.31361856 | G37: ='2026-2030年盈利测算表'!T34 -> 0.32224574 | H37: ='2026-2030年盈利测算表'!V34 -> 0.33095178 | I37: ='2026-2030年盈利测算表'!X34 -> 0.0438343
B38: 人民币市场化负债占比（日均） | C38: ='2026-2030年盈利测算表'!L37 -> 0.33330385 | D38: ='2026-2030年盈利测算表'!N37 -> 0.32185827 | E38: ='2026-2030年盈利测算表'!P37 -> 0.33462483 | F38: ='2026-2030年盈利测算表'!R37 -> 0.31515159 | G38: ='2026-2030年盈利测算表'!T37 -> 0.2950099 | H38: ='2026-2030年盈利测算表'!V37 -> 0.27277382 | I38: ='2026-2030年盈利测算表'!X37 -> -0.060530025
B39: 存贷比（一般性贷款/自营存款，人民币时点） | C39: ='2026-2030年盈利测算表'!L38 -> 0.95724308 | D39: ='2026-2030年盈利测算表'!N38 -> 0.94141015 | E39: ='2026-2030年盈利测算表'!P38 -> 0.92584271 | F39: ='2026-2030年盈利测算表'!R38 -> 0.91450875 | G39: ='2026-2030年盈利测算表'!T38 -> 0.89807765 | H39: ='2026-2030年盈利测算表'!V38 -> 0.8774872 | I39: ='2026-2030年盈利测算表'!X38 -> -0.079755884
B40: 日均存贷比（一般性贷款/自营存款） | C40: ='2026-2030年盈利测算表'!L39 -> 0.96637441 | D40: ='2026-2030年盈利测算表'!N39 -> 0.95797941 | E40: ='2026-2030年盈利测算表'!P39 -> 0.94317034 | F40: ='2026-2030年盈利测算表'!R39 -> 0.92941109 | G40: ='2026-2030年盈利测算表'!T39 -> 0.91345717 | H40: ='2026-2030年盈利测算表'!V39 -> 0.89089007 | I40: ='2026-2030年盈利测算表'!X39 -> -0.075484342
...

Sheet 2026-2030年盈利测算表
A1: 2026-2030年盈利测算表（积极情景） | AA1: 公式问题 | AB1: 回复
A2: 项目 | B2: 2020年 | D2: 2021年 | F2: 2022年 | H2: 2023年 | J2: 2024年 | L2: 2025年 | N2: 2026年 | P2: 2027年 | R2: 2028年 | T2: 2029年 | V2: 2030年 | X2: 十五五 总增量 | Y2: 十五五 复合增速
B3: 余额 | C3: 年增 | D3: 余额 | E3: 年增 | F3: 余额 | G3: 年增 | H3: 余额 | I3: 年增 | J3: 余额 | K3: 年增 | L3: 余额 | M3: 年增 | N3: 余额 | O3: 年增 | P3: 余额 | Q3: 年增 | R3: 余额 | S3: 年增 | T3: 余额 | U3: 年增 | V3: 余额 | W3: 年增
A4: 一、盈利结果
A5: （一）并表口径
A6: 归母净利润 | B6: 489.8 | C6: 9.65 | D6: 556.41 | E6: =D6-B6 -> 66.61 | F6: 621.03 | G6: =F6-D6 -> 64.62 | H6: 670.16 | I6: =H6-F6 -> 49.13 | J6: 685.76 | K6: =J6-H6 -> 15.6 | L6: 706.18 | M6: =L6-J6 -> 20.42 | N6: =N7*(1-N25-N26-N27)-10-子公司!N64 -> 757.81904 | O6: =N6-L6 -> 51.639042 | P6: =P7*(1-P25-P26-P27)-10-子公司!P64 -> 810.60057 | Q6: =P6-N6 -> 52.781523 | R6: =R7*(1-R25-R26-R27)-10-子公司!R64 -> 866.01284 | S6: =R6-P6 -> 55.412279 | T6: =T7*(1-T25-T26-T27)-10-子公司!T64 -> 927.36198 | U6: =T6-R6 -> 61.349135 | V6: =V7*(1-V25-V26-V27)-10-子公司!V64 -> 985.20062 | W6: =V6-T6 -> 57.838642 | X6: =V6-L6 -> 279.02062 | Y6: =(V6/L6)^(1/5)-1 -> 0.06886253
A7: 营业净收入 | B7: 1947.31 | C7: 71.47 | D7: 2045.57 | E7: =D7-B7 -> 98.26 | F7: 2113.92 | G7: =F7-D7 -> 68.35 | H7: 2058.96 | I7: =H7-F7 -> -54.96 | J7: 2136.46 | K7: =J7-H7 -> 77.5 | L7: 2124.75 | M7: =L7-J7 -> -11.71 | N7: =N8+N9 -> 2219.8843 | O7: =N7-L7 -> 95.134319 | P7: =P8+P9 -> 2344.467 | Q7: =P7-N7 -> 124.58265 | R7: =R8+R9 -> 2461.359 | S7: =R7-P7 -> 116.89202 | T7: =T8+T9 -> 2591.0856 | U7: =T7-R7 -> 129.72664 | V7: =V8+V9 -> 2707.3909 | W7: =V7-T7 -> 116.30528 | X7: =V7-L7 -> 582.64091 | Y7: =(V7/L7)^(1/5)-1 -> 0.049659947
A8: 其中：利息净收入 | B8: 1505.15 | C8: 35.9 | D8: 1478.96 | E8: =D8-B8 -> -26.19 | F8: 1506.47 | G8: =F8-D8 -> 27.51 | H8: 1435.39 | I8: =H8-F8 -> -71.08 | J8: 1466.79 | K8: =J8-H8 -> 31.4 | L8: 1444.69 | M8: =L8-J8 -> -22.1 | N8: =N13+子公司!N8 -> 1487.1203 | O8: =N8-L8 -> 42.430273 | P8: =P13+子公司!P8 -> 1594.5546 | Q8: =P8-N8 -> 107.43433 | R8: =R13+子公司!R8 -> 1671.7017 | S8: =R8-P8 -> 77.147054 | T8: =T13+子公司!T8 -> 1751.2832 | U8: =T8-R8 -> 79.581531 | V8: =V13+子公司!V8 -> 1811.7919 | W8: =V8-T8 -> 60.508699 | X8: =V8-L8 -> 367.10188 | Y8: =(V8/L8)^(1/5)-1 -> 0.046325305
A9: 非利息净收入 | B9: 442.16 | C9: 35.57 | D9: 566.61 | E9: =D9-B9 -> 124.45 | F9: 607.45 | G9: =F9-D9 -> 40.84 | H9: 623.57 | I9: =H9-F9 -> 16.12 | J9: 669.67 | K9: =J9-H9 -> 46.1 | L9: 680.06 | M9: =L9-J9 -> 10.39 | N9: =N14+子公司!N9-4 -> 732.76405 | O9: =N9-L9 -> 52.704046 | P9: =P14+子公司!P9-4 -> 749.91237 | Q9: =P9-N9 -> 17.148329 | R9: =R14+子公司!R9-4 -> 789.65734 | S9: =R9-P9 -> 39.744963 | T9: =T14+子公司!T9-4 -> 839.80245 | U9: =T9-R9 -> 50.145113 | V9: =V14+子公司!V9-4 -> 895.59903 | W9: =V9-T9 -> 55.796576 | X9: =V9-L9 -> 215.53903 | Y9: =(V9/L9)^(1/5)-1 -> 0.056606496 | AA9: 为什么要减4亿 | AB9: 合并抵消经验值
A10: （二）本行口径
A11: 净利润 | B11: 477.67 | C11: 21.75 | D11: 515.14 | E11: =D11-B11 -> 37.47 | F11: 578.95 | G11: =F11-D11 -> 63.81 | H11: 626.51 | I11: =H11-F11 -> 47.56 | J11: 663.72 | K11: =J11-H11 -> 37.21 | L11: 647.01 | M11: =L11-J11 -> -16.71 | N11: =N196*N12 -> 685.87278 | O11: =N11-L11 -> 38.862783 | P11: =P196*P12 -> 718.39854 | Q11: =P11-N11 -> 32.525753 | R11: =R196*R12 -> 762.80085 | S11: =R11-P11 -> 44.40232 | T11: =T196*T12 -> 811.01314 | U11: =T11-R11 -> 48.212286 | V11: =V196*V12 -> 855.33941 | W11: =V11-T11 -> 44.32627 | X11: =V11-L11 -> 208.32941 | Y11: =(V11/L11)^(1/5)-1 -> 0.057415076
A12: 营业净收入（本行） | B12: =B13+B14 -> 1853.01 | C12: =C13+C14 -> 73.073854 | D12: 1914 | E12: =D12-B12 -> 60.99 | F12: 1981 | G12: =F12-D12 -> 67 | H12: 1912 | I12: =H12-F12 -> -69 | J12: 2003 | K12: =J12-H12 -> 91 | L12: =L13+L14 -> 1941.64 | M12: =M13+M14 -> -12 | N12: =N13+N14 -> 2027.8379 | O12: =O13+O14 -> 86.197861 | P12: =P13+P14 -> 2090.0167 | Q12: =Q13+Q14 -> 62.178834 | R12: =R13+R14 -> 2184.245 | S12: =S13+S14 -> 94.228327 | ... W12: =W13+W14 -> 88.143095 | X12: =V12-L12 -> 432.79497 | Y12: =(V12/L12)^(1/5)-1 -> 0.041066122
A13: 其中：利息净收入 | B13: 1261.15 | C13: 62.947601 | D13: 1412 | E13: =D13-B13 -> 150.85 | F13: 1426 | G13: =F13-D13 -> 14 | H13: 1351 | I13: =H13-F13 -> -75 | J13: 1381 | K13: =J13-H13 -> 30 | L13: 1359.33 | M13: -22 | N13: =息差测算表!C6 -> 1398.7484 | O13: =N13-L13 -> 39.418442 | P13: =息差测算表!D6 -> 1456.7307 | Q13: =P13-N13 -> 57.982301 | R13: =息差测算表!E6 -> 1520.0171 | S13: =R13-P13 -> 63.286398 | T13: =息差测算表!F6 -> 1582.4091 | U13: =T13-R13 -> 62.391913 | V13: =息差测算表!G6 -> 1625.5724 | W13: =V13-T13 -> 43.163371 | X13: =V13-L13 -> 266.24242 | Y13: =(V13/L13)^(1/5)-1 -> 0.036421192 | AA13: 和息差表链接
A14: 非利息净收入 | B14: 591.86 | C14: 10.126253 | D14: 501.78 | E14: =D14-B14 -> -90.08 | F14: 554.82 | G14: =F14-D14 -> 53.04 | H14: 560.41 | I14: =H14-F14 -> 5.59 | J14: 622.12 | K14: =J14-H14 -> 61.71 | L14: 582.31 | M14: 10 | N14: =中收测算表!B9 -> 629.08942 | O14: =N14-L14 -> 46.779419 | P14: =中收测算表!B10 -> 633.28595 | Q14: =P14-N14 -> 4.1965335 | R14: =中收测算表!B11 -> 664.22788 | S14: =R14-P14 -> 30.941929 | T14: =中收测算表!B12 -> 703.88282 | U14: =T14-R14 -> 39.654941 | V14: =中收测算表!B13 -> 748.86255 | W14: =V14-T14 -> 44.979724 | X14: =V14-L14 -> 166.55255 | Y14: =(V14/L14)^(1/5)-1 -> 0.051597566 | Z14: 和后面链接
A15: 二、一级核心指标
A16: 总资产 | B16: 75112 | C16: 7608 | D16: 80429 | E16: =D16-B16 -> 5317 | F16: 85475 | G16: =F16-D16 -> 5046 | H16: 90525 | I16: =H16-F16 -> 5050 | J16: 95327 | K16: =J16-H16 -> 4802 | L16: 101316.58 | M16: 5989.36 | N16: =L16+O16 -> 107999.58 | O16: 6683 | P16: =N16+Q16 -> 114699.58 | Q16: =5200+1500 -> 6700 | R16: =P16+S16 -> 119599.58 | S16: =5400-500 -> 4900 | T16: =R16+U16 -> 124699.58 | U16: =5600-500 -> 5100 | V16: =T16+W16 -> 129999.58 | W16: =5800-500 -> 5300 | X16: =V16-L16 -> 28683 | Y16: =(V16/L16)^(1/5)-1 -> 0.051119966
A17: ROE | B17: 0.1011 | C17: -0.0096 | D17: 0.1073 | E17: =D17-B17 -> 0.0062 | F17: 0.108 | G17: =F17-D17 -> 0.0007 | H17: 0.108 | I17: =H17-F17 -> 0 | J17: 0.0979 | K17: =J17-H17 -> -0.0101 | L17: 0.0939 | M17: =L17-J17 -> -0.004 | N17: =资本!D76 -> 0.095294354 | O17: =N17-L17 -> 0.0013943536 | P17: =资本!E76 -> 0.095069286 | Q17: =P17-N17 -> -0.00022506801 | R17: =资本!F76 -> 0.0922937 | S17: =R17-P17 -> -0.0027755852 | T17: =资本!G76 -> 0.091916814 | U17: =T17-R17 -> -0.00037688674 | V17: =资本!H76 -> 0.091152488 | W17: =V17-T17 -> -0.00076432555 | X17: =V17-L17 -> -0.0027475118
A18: RAROC | B18: ='[1]2.年化RAROC（并表）-底稿'!$I$13 -> 0.085713918 | D18: ='[1]2.年化RAROC（并表）-底稿'!$M$13 -> 0.091498466 | E18: =D18-B18 -> 0.0057845486 | F18: ='[1]2.年化RAROC（并表）-底稿'!$Q$13 -> 0.094395276 | G18: =F18-D18 -> 0.0028968094 | H18: ='[1]2.年化RAROC（并表）-底稿'!$U$13 -> 0.094876189 | I18: =H18-F18 -> 0.00048091322 | J18: ='[1]2.年化RAROC（并表）-底稿'!$Y$13 -> 0.091549249 | K18: =J18-H18 -> -0.0033269398 | L18: 0.0881 | M18: =L18-J18 -> -0.003449249 | N18: =资本!D94 -> 0.087980207 | O18: =N18-L18 -> -0.00011979261 | P18: =资本!E94 -> 0.087539869 | Q18: =P18-N18 -> -0.0004403382 | R18: =资本!F94 -> 0.087814458 | S18: =R18-P18 -> 0.00027458925 | T18: =资本!G94 -> 0.089743652 | U18: =T18-R18 -> 0.0019291932 | V18: =资本!H94 -> 0.090961541 | W18: =V18-T18 -> 0.0012178897 | X18: =V18-L18 -> 0.0028615414
A19: 核心一级资本充足率 | B19: 0.0874 | C19: ='[1]1.1核心一级资本充足率（并表）-底稿'!$I$14-'[1]1.1核心一级资本充足率（并表）-底稿'!$E$14 -> 0.0005 | D19: 0.0885 | E19: =D19-B19 -> 0.0011 | F19: 0.0874 | G19: =F19-D19 -> -0.0011 | H19: 0.0899 | I19: =H19-F19 -> 0.0025 | J19: 0.0972 | K19: =J19-H19 -> 0.0073 | L19: 0.0948 | M19: =L19-J19 -> -0.0024 | N19: =资本!D84 -> 0.095730282 | O19: =N19-L19 -> 0.00093028246 | P19: =资本!E84 -> 0.099696284 | Q19: =P19-N19 -> 0.0039660017 | R19: =资本!F84 -> 0.10129985 | S19: =R19-P19 -> 0.0016035683 | T19: =资本!G84 -> 0.10303652 | U19: =T19-R19 -> 0.0017366681 | V19: =资本!H84 -> 0.10472588 | W19: =V19-T19 -> 0.0016893626 | X19: =V19-L19 -> 0.0099258831
A20: 三、二级核心指标（并表）
A21: 生息资产日均 | B21: 66678.02 | D21: 72251.78 | E21: =D21-B21 -> 5573.76 | F21: 76386.39 | G21: =F21-D21 -> 4134.61 | H21: 80467.13 | I21: =H21-F21 -> 4080.74 | J21: 83098.45 | K21: =J21-H21 -> 2631.32 | L21: 88562.26 | M21: =L21-J21 -> 5463.81 | N21: =L21+O21 -> 92357.244 | O21: =O53+子公司!O15 -> 3794.984 | P21: =N21+Q21 -> 100806.96 | Q21: =Q53+子公司!Q15 -> 8449.7175 | R21: =P21+S21 -> 106212.59 | S21: =S53+子公司!S15 -> 5405.6249 | T21: =R21+U21 -> 110798.4 | U21: =U53+子公司!U15 -> 4585.816 | V21: =T21+W21 -> 115610.38 | W21: =W53+子公司!W15 -> 4811.9801 | X21: =V21-L21 -> 27048.122 | Y21: =(V21/L21)^(1/5)-1 -> 0.054750232
A22: 生息资产占比（日均） | B22: =B21/(B16+B16-C16)*2 -> 0.93507068 | D22: =D21/(B16+D16)*2 -> 0.92903839 | E22: =D22-B22 -> -0.0060322907 | F22: =F21/(D16+F16)*2 -> 0.92085049 | G22: =F22-D22 -> -0.0081878967 | H22: =H21/(F16+H16)*2 -> 0.9143992 | I22: =H22-F22 -> -0.0064512873 | J22: =J21/(H16+J16)*2 -> 0.89424327 | K22: =J22-H22 -> -0.020155936 | L22: =L21/(J16+L16)*2 -> 0.90073889 | M22: =L22-J22 -> 0.0064956213 | N22: =(N53+子公司!N15)/(N51+子公司!N13) -> 0.91384354 | O22: =N22-L22 -> 0.013104646 | P22: =(P53+子公司!P15)/(P51+子公司!P13) -> 0.91260154 | Q22: =P22-N22 -> -0.0012419982 | R22: =(R53+子公司!R15)/(R51+子公司!R13) -> 0.91416923 | S22: =R22-P22 -> 0.0015676911 | T22: =(T53+子公司!T15)/(T51+子公司!T13) -> 0.91566453 | U22: =T22-R22 -> 0.0014953025 | V22: =(V53+子公司!V15)/(V51+子公司!V13) -> 0.91707937 | W22: =V22-T22 -> 0.0014148367 | X22: =V22-L22 -> 0.016340478 | AA22: 为什么减1000 | AB22: 合并抵消经验值
A23: 净息差 | B23: =B8/B21 -> 0.022573406 | C23: -0.0019 | D23: =D8/D21 -> 0.02046953 | E23: =D23-B23 -> -0.0021038754 | F23: =F8/F21 -> 0.019721707 | G23: =F23-D23 -> -0.00074782333 | H23: =H8/H21 -> 0.017838215 | I23: =H23-F23 -> -0.0018834915 | J23: =J8/J21 -> 0.017651232 | K23: =J23-H23 -> -0.00018698367 | L23: =L8/L21 -> 0.016312705 | M23: =L23-J23 -> -0.001338527 | N23: =N8/N21 -> 0.016101826 | O23: =N23-L23 -> -0.00021087876 | P23: =P8/P21 -> 0.015817902 | Q23: =P23-N23 -> -0.00028392439 | R23: =R8/R21 -> 0.015739205 | S23: =R23-P23 -> -7.8696776e-05 | T23: =T8/T21 -> 0.015806033 | U23: =T23-R23 -> 6.6827984e-05 | V23: =V8/V21 -> 0.015671533 | W23: =V23-T23 -> -0.00013450017 | X23: =V23-L23 -> -0.00064117211
A24: 非息收入占比 | B24: =B9/B7 -> 0.22706195 | C24: 0.0103 | D24: =D9/D7 -> 0.2769937 | E24: =D24-B24 -> 0.049931752 | F24: =F9/F7 -> 0.28735714 | G24: =F24-D24 -> 0.010363439 | H24: =H9/H7 -> 0.30285678 | I24: =H24-F24 -> 0.015499645 | J24: =J9/J7 -> 0.31344841 | K24: =J24-H24 -> 0.010591633 | L24: =L9/L7 -> 0.32006589 | M24: =L24-J24 -> 0.0066174754 | N24: =N9/N7 -> 0.3300911 | O24: =N24-L24 -> 0.010025205 | P24: =P9/P7 -> 0.31986476 | Q24: =P24-N24 -> -0.010226331 | R24: =R9/R7 -> 0.32082168 | S24: =R24-P24 -> 0.00095692065 | T24: =T9/T7 -> 0.32411219 | U24: =T24-R24 -> 0.0032905099 | V24: =V9/V7 -> 0.33079783 | W24: =V24-T24 -> 0.0066856316 | X24: =V24-L24 -> 0.010731936
A25: 成本收入比 | B25: 0.26653178 | C25: -0.0105 | D25: 0.29203107 | E25: =D25-B25 -> 0.025499292 | F25: 0.30534741 | G25: =F25-D25 -> 0.013316339 | H25: 0.32352256 | I25: =H25-F25 -> 0.018175144 | J25: 0.32488322 | K25: =J25-H25 -> 0.001360663 | L25: 0.31607954 | M25: =L25-J25 -> -0.0088036793 | N25: =L25+O25 -> 0.31607954 | O25: 0 | P25: =N25+Q25 -> 0.31557954 | Q25: -0.0005 | R25: =P25+S25 -> 0.31507954 | S25: -0.0005 | T25: =R25+U25 -> 0.31457954 | U25: -0.0005 | V25: =T25+W25 -> 0.31407954 | W25: -0.0005 | X25: =V25-L25 -> -0.002
A26: 风险成本率 | B26: 0.42617251 | C26: 0.0144 | D26: 0.37665785 | E26: =D26-B26 -> -0.049514664 | F26: 0.33778005 | G26: =F26-D26 -> -0.038877802 | H26: 0.30211369 | I26: =H26-F26 -> -0.03566636 | J26: 0.28604795 | K26: =J26-H26 -> -0.01606574 | L26: 0.2737828 | M26: =L26-J26 -> -0.01226515 | N26: =L26+O26 -> 0.2687828 | O26: -0.005 | P26: =N26+Q26 -> 0.2637828 | Q26: -0.005 | R26: =P26+S26 -> 0.2587828 | S26: -0.005 | T26: =R26+U26 -> 0.2537828 | U26: -0.005 | V26: =T26+W26 -> 0.2487828 | W26: -0.005 | X26: =V26-L26 -> -0.025
A27: 税务成本率 | B27: 0.053145108 | C27: 0.3%% | D27: 0.055451537 | E27: =D27-B27 -> 0.0023064289 | F27: 0.059548138 | G27: =F27-D27 -> 0.0040966013 | H27: 0.043759956 | I27: =H27-F27 -> -0.015788182 | J27: 0.063605216 | K27: =J27-H27 -> 0.01984526 | L27: 0.069255206 | M27: =L27-J27 -> 0.0056499904 | N27: =L27+O27 -> 0.069255206 | O27: 0 | P27: =N27+Q27 -> 0.069255206 | Q27: 0 | R27: =P27+S27 -> 0.069255206 | S27: 0 | T27: =R27+U27 -> 0.069255206 | U27: 0 | V27: =T27+W27 -> 0.069255206 | W27: 0 | X27: =V27-L27 -> 0
A28: 综合风险权重 | B28: 0.73672221 | D28: 0.72024808 | E28: =D28-B28 -> -0.01647413 | F28: 0.7308449 | G28: =F28-D28 -> 0.010596825 | H28: 0.74109085 | I28: =H28-F28 -> 0.010245949 | J28: 0.74233501 | K28: =J28-H28 -> 0.0012441539 | L28: =资本!C93 -> 0.75026761 | M28: =L28-J28 -> 0.0079326091 | N28: =资本!D93 -> 0.75809131 | O28: =N28-L28 -> 0.0078236989 | P28: =资本!E93 -> 0.7653228 | Q28: =P28-N28 -> 0.0072314833 | R28: =资本!F93 -> 0.77412488 | S28: =R28-P28 -> 0.0088020822 | T28: =资本!G93 -> 0.77735417 | U28: =T28-R28 -> 0.0032292919 | V28: =资本!H93 -> 0.78102084 | W28: =V28-T28 -> 0.003666673 | X28: =V28-L28 -> 0.030753229
A29: 四、其他指标（本行）
A30: 净息差 | B30: 0.0228 | C30: -0.0019 | D30: 0.0206 | E30: -0.0022 | F30: 0.0197 | G30: -0.0009 | H30: 0.0178 | I30: -0.0019 | J30: 0.017601992 | K30: -0.0002 | L30: =L13/L53 -> 0.016376089 | M30: -0.0012 | N30: =息差测算表!C7 -> 0.016226546 | O30: =N30-L30 -> -0.000149543 | P30: =息差测算表!D7 -> 0.015620824 | Q30: =P30-N30 -> -0.00060572192 | R30: =息差测算表!E7 -> 0.015656156 | S30: =R30-P30 -> 3.5331662e-05 | T30: =息差测算表!F7 -> 0.016 | U30: =T30-R30 -> 0.0003438445 | V30: =息差测算表!G7 -> 0.015529954 | W30: =V30-T30 -> -0.00047004641 | X30: =V30-L30 -> -0.00084613518 | Z30: 和后面链接
A31: 信贷资产占比（各项贷款/总资产，时点，人民币） | B31: =B57/B55 -> 0.61457084 | C31: -0.005 | D31: =D57/D55 -> 0.61682948 | E31: =D31-B31 -> 0.0022586486 | F31: =F57/F55 -> 0.62652337 | G31: =F31-D31 -> 0.0096938884 | H31: =H57/H55 -> 0.6335629 | I31: =H31-F31 -> 0.0070395265 | J31: =J57/J55 -> 0.64209499 | K31: =J31-H31 -> 0.0085320943 | L31: =L57/L55 -> 0.62312869 | M31: =L31-J31 -> -0.018966302 | N31: =N57/N55 -> 0.60872968 | O31: =N31-L31 -> -0.014399011 | P31: =P57/P55 -> 0.60660646 | Q31: =P31-N31 -> -0.0021232184 | R31: =R57/R55 -> 0.60564704 | S31: =R31-P31 -> -0.0009594238 | T31: =T57/T55 -> 0.60618142 | U31: =T31-R31 -> 0.00053438178 | V31: =V57/V55 -> 0.60655446 | W31: =V31-T31 -> 0.00037303719 | X31: =V31-L31 -> -0.016574234 | AA31: 改了公式需要核对
A32: 信贷资产占比（一般贷款/总资产，时点，人民币） | B32: =(B60+B63+B66)/B55 -> 0.54174354 | C32: -0.007 | D32: =(D60+D63+D66)/D55 -> 0.54068118 | E32: =D32-B32 -> -0.0010623591 | F32: =(F60+F63+F66)/F55 -> 0.54122397 | G32: =F32-D32 -> 0.00054279496 | H32: =(H60+H63+H66)/H55 -> 0.55391716 | I32: =H32-F32 -> 0.012693188 | J32: =(J60+J63+J66)/J55 -> 0.55988363 | K32: =J32-H32 -> 0.0059664652 | L32: =(L60+L63+L66)/L55 -> 0.56379388 | M32: =L32-J32 -> 0.0039102567 | N32: =(N60+N63+N66)/N55 -> 0.56215249 | O32: =N32-L32 -> -0.0016413942 | P32: =(P60+P63+P66)/P55 -> 0.56811999 | Q32: =P32-N32 -> 0.0059675034 | R32: =(R60+R63+R66)/R55 -> 0.57145845 | S32: =R32-P32 -> 0.0033384572 | T32: =(T60+T63+T66)/T55 -> 0.57188144 | U32: =T32-R32 -> 0.00042299314 | V32: =(V60+V63+V66)/V55 -> 0.56995208 | W32: =V32-T32 -> -0.0019293602 | X32: =V32-L32 -> 0.0061581994
A33: 自营存款占比（时点，人民币） | B33: =B125/B123 -> 0.65192009 | D33: =D125/D123 -> 0.64141497 | E33: =D33-B33 -> -0.010505122 | F33: =F125/F123 -> 0.65129927 | G33: =F33-D33 -> 0.0098842976 | H33: =H125/H123 -> 0.65983082 | I33: =H33-F33 -> 0.0085315468 | J33: =J125/J123 -> 0.67429979 | K33: =J33-H33 -> 0.014468979 | L33: =L125/L123 -> 0.66132456 | M33: =L33-J33 -> -0.012975238 | N33: =N125/N123 -> 0.65691877 | O33: =N33-L33 -> -0.0044057878 | P33: =P125/P123 -> 0.6767207 | Q33: =P33-N33 -> 0.019801928 | R33: =R125/R123 -> 0.69682107 | S33: =R33-P33 -> 0.020100369 | T33: =T125/T123 -> 0.7168917 | U33: =T33-R33 -> 0.020070633 | V33: =V125/V123 -> 0.73792925 | W33: =V33-T33 -> 0.021037551 | X33: =V33-L33 -> 0.076604693
A34: 零售存款占比（日均） | B34: =B134/B126 -> 0.18818642 | D34: =D134/D126 -> 0.18526335 | E34: =D34-B34 -> -0.0029230609 | F34: =F134/F126 -> 0.20445224 | G34: =F34-D34 -> 0.019188884 | H34: =H134/H126 -> 0.25222505 | I34: =H34-F34 -> 0.047772813 | J34: =J134/J126 -> 0.27145961 | K34: =J34-H34 -> 0.019234559 | L34: =L134/L126 -> 0.28711748 | M34: =L34-J34 -> 0.015657871 | N34: =N134/N126 -> 0.29448384 | O34: =N34-L34 -> 0.0073663559 | P34: =P134/P126 -> 0.30511638 | Q34: =P34-N34 -> 0.010632542 | R34: =R134/R126 -> 0.31361856 | S34: =R34-P34 -> 0.0085021806 | T34: =T134/T126 -> 0.32224574 | U34: =T34-R34 -> 0.0086271772 | V34: =V134/V126 -> 0.33095178 | W34: =V34-T34 -> 0.0087060446 | X34: =V34-L34 -> 0.0438343
A35: 对公活期占比（日均） | B35: =B131/B128 -> 0.50198314 | C35: -0.013 | D35: =D131/D128 -> 0.52313402 | E35: =D35-B35 -> 0.021150887 | F35: =F131/F128 -> 0.52047447 | G35: =F35-D35 -> -0.0026595479 | H35: =H131/H128 -> 0.54948243 | I35: =H35-F35 -> 0.029007957 | J35: =J131/J128 -> 0.52117308 | K35: =J35-H35 -> -0.028309352 | L35: =L131/L128 -> 0.45808969 | M35: =L35-J35 -> -0.063083393 | N35: =N131/N128 -> 0.43431898 | O35: =N35-L35 -> -0.023770702 | P35: =P131/P128 -> 0.43703864 | Q35: =P35-N35 -> 0.0027196534 | R35: =R131/R128 -> 0.43982351 | S35: =R35-P35 -> 0.002784872 | T35: =T131/T128 -> 0.44237246 | U35: =T35-R35 -> 0.0025489494 | V35: =V131/V128 -> 0.44494973 | W35: =V35-T35 -> 0.0025772677 | X35: =V35-L35 -> -0.01313996
A36: 零售活期占比（日均） | B36: =B137/B134 -> 0.33573981 | C36: -0.005 | D36: =D137/D134 -> 0.32881985 | E36: =D36-B36 -> -0.0069199527 | F36: =F137/F134 -> 0.28964125 | G36: =F36-D36 -> -0.0391786 | H36: =H137/H134 -> 0.24033569 | I36: =H36-F36 -> -0.049305561 | J36: =J137/J134 -> 0.268133 | K36: =J36-H36 -> 0.027797312 | L36: =L137/L134 -> 0.27089068 | M36: =L36-J36 -> 0.0027576712 | N36: =N137/N134 -> 0.274 | O36: =N36-L36 -> 0.0031093242 | P36: =P137/P134 -> 0.27630762 | Q36: =P36-N36 -> 0.0023076219 | R36: =R137/R134 -> 0.27823901 | S36: =R36-P36 -> 0.0019313898 | T36: =T137/T134 -> 0.27997359 | U36: =T36-R36 -> 0.0017345761 | V36: =V137/V134 -> 0.28161176 | W36: =V36-T36 -> 0.0016381723 | X36: =V36-L36 -> 0.010721084
A37: 人民币市场化负债占比（日均） | B37: =B140/B124 -> 0.34406719 | D37: =D140/D124 -> 0.3595394 | E37: =D37-B37 -> 0.015472212 | F37: =F140/F124 -> 0.346706 | G37: =F37-D37 -> -0.012833405 | H37: =H140/H124 -> 0.3190469 | I37: =H37-F37 -> -0.027659099 | J37: =J140/J124 -> 0.3302094 | K37: =J37-H37 -> 0.011162502 | L37: =L140/L124 -> 0.33330385 | M37: =L37-J37 -> 0.0030944467 | N37: =N140/N124 -> 0.32185827 | O37: =N37-L37 -> -0.011445579 | P37: =P140/P124 -> 0.33462483 | Q37: =P37-N37 -> 0.012766566 | R37: =R140/R124 -> 0.31515159 | S37: =R37-P37 -> -0.019473248 | T37: =T140/T124 -> 0.2950099 | U37: =T37-R37 -> -0.020141684 | V37: =V140/V124 -> 0.27277382 | W37: =V37-T37 -> -0.02223608 | X37: =V37-L37 -> -0.060530025
A38: 存贷比（一般性贷款/自营存款，人民币时点） | B38: =(B60+B63+B66+B69-1400)/(B127+B133) -> 0.98271752 | C38: -0.014295428 | D38: =(D60+D63+D66+D69-1600)/(D127+D133) -> 1.0080291 | E38: =D38-B38 -> 0.025311595 | F38: =(F60+F63+F66+F69-2400)/(F127+F133) -> 0.98310593 | G38: =F38-D38 -> -0.024923186 | H38: =(H60+H63+H66+H69-2400)/(H127+H133) -> 0.99161678 | I38: =H38-F38 -> 0.0085108523 | J38: =(J60+J63+J66+J69-2100)/(J127+J133) -> 0.98406336 | K38: =J38-H38 -> -0.007553418 | L38: =(L60+L63+L66+L69-2110)/(L127+L133) -> 0.95724308 | M38: =L38-J38 -> -0.026820283 | N38: =(N60+N63+N66+N69-2110)/(N127+N133) -> 0.94141015 | O38: =N38-L38 -> -0.015832933 | P38: =(P60+P63+P66+P69-2310)/(P127+P133) -> 0.92584271 | Q38: =P38-N38 -> -0.015567438 | R38: =(R60+R63+R66+R69-2310)/(R127+R133) -> 0.91450875 | S38: =R38-P38 -> -0.011333964 | T38: =(T60+T63+T66+T69-2310)/(T127+T133) -> 0.89807765 | U38: =T38-R38 -> -0.016431096 | V38: =(V60+V63+V66+V69-2310)/(V127+V133) -> 0.8774872 | W38: =V38-T38 -> -0.020590453 | X38: =V38-L38 -> -0.079755884
A39: 日均（一般性贷款/自营存款） | B39: =(B61+B64+B67+B70-1400)/(B128+B134) -> 0.95918332 | C39: -0.031245693 | D39: =(D61+D64+D67+D70-1500)/(D128+D134) -> 1.0041105 | E39: =D39-B39 -> 0.044927142 | F39: =(F61+F64+F67+F70-2200)/(F128+F134) -> 0.97230514 | G39: =F39-D39 -> -0.031805324 | H39: =(H61+H64+H67+H70-2400)/(H128+H134) -> 0.9407307 | I39: =H39-F39 -> -0.031574434 | J39: =(J61+J64+J67+J70-1930)/(J128+J134) -> 0.99709123 | K39: =J39-H39 -> 0.056360527 | L39: =(L61+L64+L67+L70-2200)/(L128+L134) -> 0.96637441 | M39: =L39-J39 -> -0.030716821 | N39: =(N61+N64+N67+N70-2110)/(N128+N134) -> 0.95797941 | O39: =N39-L39 -> -0.0083949928 | P39: =(P61+P64+P67+P70-2310)/(P128+P134) -> 0.94317034 | Q39: =P39-N39 -> -0.014809076 | R39: =(R61+R64+R67+R70-2310)/(R128+R134) -> 0.92941109 | S39: =R39-P39 -> -0.013759248 | T39: =(T61+T64+T67+T70-2310)/(T128+T134) -> 0.91345717 | U39: =T39-R39 -> -0.015953925 | V39: =(V61+V64+V67+V70-2310)/(V128+V134) -> 0.89089007 | W39: =V39-T39 -> -0.0225671 | X39: =V39-L39 -> -0.075484342
A40: 外币资负差（负债-资产，时点，亿美元） | B40: =B142-B98 -> -41.91 | D40: =D142-D98 -> -27.08 | E40: =D40-B40 -> 14.83 | F40: =F142-F98 -> -46 | G40: =F40-D40 -> -18.92 | H40: =H142-H98 -> -42.5 | I40: =H40-F40 -> 3.5 | J40: =J142-J98 -> -47.23 | K40: =J40-H40 -> -4.73 | L40: =L142-L98 -> 0.52633377 | M40: =L40-J40 -> 47.756334 | N40: =N142-N98 -> -134.47367 | O40: =N40-L40 -> -135 | P40: =P142-P98 -> -114.47367 | Q40: =P40-N40 -> 20 | R40: =R142-R98 -> -44.473666 | S40: =R40-P40 -> 70 | T40: =T142-T98 -> 25.526334 | U40: =T40-R40 -> 70 | V40: =V142-V98 -> 95.526334 | W40: =V40-T40 -> 70 | X40: =V40-L40 -> 95
...

Sheet 板块（积极-原版本）
A1: 板块条线收入预测（积极情景）
A2: 板块 | B2: 指标 | C2: 2023年 | D2: 2024年 | F2: 2025年 | H2: 2026年 | J2: 2027年 | L2: 2028年 | N2: 2029年 | P2: 2030年
D3: 当年 | E3: 比上年 | F3: 当年 | G3: 比上年 | H3: 当年 | I3: 比上年 | J3: 当年 | K3: 比上年 | L3: 当年 | M3: 比上年 | N3: 当年 | O3: 比上年 | P3: 当年 | Q3: 比上年 | S3: 2026 | U3: 2027 | W3: 2028 | Y3: 2029 | AA3: 2030
A4: 三大板块合计占比 | B4: 一、营业净收入 | C4: =(C10+C27+C44)/'2026-2030年盈利测算表'!H12 -> 0.95686173 | D4: =(D10+D27+D44)/'2026-2030年盈利测算表'!J12 -> 0.91533694 | E4: =D4-C4 -> -0.04152479 | F4: =(F10+F27+F44)/'2026-2030年盈利测算表'!L12 -> 0.92221266 | G4: =F4-D4 -> 0.0068757152 | H4: =(H10+H27+H44)/S4 -> 0.92019874 | I4: =H4-F4 -> -0.0020139139 | J4: =(J10+J27+J44)/U4 -> 0.91155639 | K4: =J4-H4 -> -0.0086423544 | L4: =(L10+L27+L44)/W4 -> 0.91676492 | M4: =L4-J4 -> 0.0052085325 | N4: =(N10+N27+N44)/Y4 -> 0.93461815 | O4: =N4-L4 -> 0.017853234 | P4: =(P10+P27+P44)/AA4 -> 0.92879635 | Q4: =P4-N4 -> -0.0058218052 | S4: ='2026-2030年盈利测算表'!N12 -> 2027.8379 | U4: ='2026-2030年盈利测算表'!P12 -> 2090.0167 | W4: ='2026-2030年盈利测算表'!R12 -> 2184.245 | Y4: ='2026-2030年盈利测算表'!T12 -> 2286.2919 | AA4: ='2026-2030年盈利测算表'!V12 -> 2374.435
B5: （一）利息净收入 | C5: =(C11+C28+C45)/'2026-2030年盈利测算表'!H13 -> 0.90976725 | D5: =(D11+D28+D45)/'2026-2030年盈利测算表'!J13 -> 0.86587508 | E5: =D5-C5 -> -0.043892171 | F5: =(F11+F28+F45)/'2026-2030年盈利测算表'!L13 -> 0.85895075 | G5: =F5-D5 -> -0.0069243253 | H5: =(H11+H28+H45)/S5 -> 0.85520408 | I5: =H5-F5 -> -0.0037466774 | J5: =(J11+J28+J45)/U5 -> 0.84516172 | K5: =J5-H5 -> -0.010042359 | L5: =(L11+L28+L45)/W5 -> 0.85361029 | M5: =L5-J5 -> 0.0084485723 | N5: =(N11+N28+N45)/Y5 -> 0.87980918 | O5: =N5-L5 -> 0.02619889 | P5: =(P11+P28+P45)/AA5 -> 0.87095161 | Q5: =P5-N5 -> -0.0088575659 | S5: ='2026-2030年盈利测算表'!N13 -> 1398.7484 | U5: ='2026-2030年盈利测算表'!P13 -> 1456.7307 | W5: ='2026-2030年盈利测算表'!R13 -> 1520.0171 | Y5: ='2026-2030年盈利测算表'!T13 -> 1582.4091 | AA5: ='2026-2030年盈利测算表'!V13 -> 1625.5724
B6: （二）非息净收入 | C6: =(C12+C29+C46)/'2026-2030年盈利测算表'!H14 -> 1.0714014 | D6: =(D12+D29+D46)/'2026-2030年盈利测算表'!J14 -> 1.0249573 | E6: =D6-C6 -> -0.046444176 | F6: =(F12+F29+F46)/'2026-2030年盈利测算表'!L14 -> 1.0698897 | G6: =F6-D6 -> 0.044932413 | H6: =(H12+H29+H46)/S6 -> 1.0647111 | I6: =H6-F6 -> -0.0051785817 | J6: =(J12+J29+J46)/U6 -> 1.0642823 | K6: =J6-H6 -> -0.00042881459 | L6: =(L12+L29+L46)/W6 -> 1.0612878 | M6: =L6-J6 -> -0.0029944808 | N6: =(N12+N29+N46)/Y6 -> 1.057835 | O6: =N6-L6 -> -0.0034527962 | P6: =(P12+P29+P46)/AA6 -> 1.0543612 | Q6: =P6-N6 -> -0.0034738048 | S6: ='2026-2030年盈利测算表'!N14 -> 629.08942 | U6: ='2026-2030年盈利测算表'!P14 -> 633.28595 | W6: ='2026-2030年盈利测算表'!R14 -> 664.22788 | Y6: ='2026-2030年盈利测算表'!T14 -> 703.88282 | AA6: ='2026-2030年盈利测算表'!V14 -> 748.86255
B7: 二、净利润 | C7: =(C18+C35+C52)/'2026-2030年盈利测算表'!H11 -> 0.94393636 | D7: =(D18+D35+D52)/'2026-2030年盈利测算表'!J11 -> 0.90055308 | E7: =D7-C7 -> -0.043383282 | F7: =(F18+F35+F52)/'2026-2030年盈利测算表'!L11 -> 0.93963105 | G7: =F7-D7 -> 0.039077971 | H7: =(H18+H35+H52)/S7 -> 0.94100599 | I7: =H7-F7 -> 0.0013749408 | J7: =(J18+J35+J52)/U7 -> 0.91865229 | K7: =J7-H7 -> -0.022353701 | L7: =(L18+L35+L52)/W7 -> 0.94023692 | M7: =L7-J7 -> 0.021584634 | N7: =(N18+N35+N52)/Y7 -> 0.99145835 | O7: =N7-L7 -> 0.051221429 | P7: =(P18+P35+P52)/AA7 -> 0.97303126 | Q7: =P7-N7 -> -0.018427087 | S7: ='2026-2030年盈利测算表'!N11 -> 685.87278 | U7: ='2026-2030年盈利测算表'!P11 -> 718.39854 | W7: ='2026-2030年盈利测算表'!R11 -> 762.80085 | Y7: ='2026-2030年盈利测算表'!T11 -> 811.01314 | AA7: ='2026-2030年盈利测算表'!V11 -> 855.33941
A8: 公司业务板块 | B8: 对公板块占全行营收比 | C8: =C10/'2026-2030年盈利测算表'!$H$12 -> 0.39484836 | D8: =D10/'2026-2030年盈利测算表'!$J$12 -> 0.37888875 | E8: =D8-C8 -> -0.015959606 | F8: =F10/'2026-2030年盈利测算表'!$L$12 -> 0.40487602 | G8: =F8-D8 -> 0.025987265 | H8: =H10/S$4 -> 0.40420503 | I8: =H8-F8 -> -0.00067098598 | J8: =J10/U$4 -> 0.40738358 | K8: =J8-H8 -> 0.0031785531 | L8: =L10/W$4 -> 0.41589065 | M8: =L8-J8 -> 0.0085070713 | N8: =N10/Y$4 -> 0.42747467 | O8: =N8-L8 -> 0.011584012 | P8: =P10/AA$4 -> 0.42520141 | Q8: =P8-N8 -> -0.0022732528
B9: 对公板块占全行净利润比 | C9: =C18/'2026-2030年盈利测算表'!$H$11 -> 0.56009657 | D9: =D18/'2026-2030年盈利测算表'!$J$11 -> 0.52600875 | E9: =D9-C9 -> -0.034087815 | F9: =F18/'2026-2030年盈利测算表'!$L$11 -> 0.46529463 | G9: =F9-D9 -> -0.060714125 | H9: =H18/S$7 -> 0.46161203 | I9: =H9-F9 -> -0.0036826005 | J9: =J18/U$7 -> 0.4621097 | K9: =J9-H9 -> 0.00049767392 | L9: =L18/W$7 -> 0.4909752 | M9: =L9-J9 -> 0.028865501 | N9: =N18/Y$7 -> 0.45829759 | O9: =N9-L9 -> -0.032677617 | P9: =P18/AA$7 -> 0.38469681 | Q9: =P9-N9 -> -0.073600777
B10: 一、营业净收入 | C10: 754.95006 | D10: 758.91417 | E10: =D10-C10 -> 3.964109 | F10: 786.12347 | G10: =F10-D10 -> 27.209299 | H10: =H11+H12 -> 819.66226 | I10: =I11+I12 -> 33.538796 | J10: =J11+J12 -> 851.43849 | K10: =K11+K12 -> 31.776227 | L10: =L11+L12 -> 908.40709 | M10: =M11+M12 -> 56.968602 | N10: =N11+N12 -> 977.33186 | O10: =O11+O12 -> 68.924766 | ... Q10: =Q11+Q12 -> 32.281249
B11: （一）利息净收入 | C11: 662.43869 | D11: 655.02325 | E11: =D11-C11 -> -7.41544 | F11: 675.2832 | G11: =F11-D11 -> 20.259947 | H11: =F11+I11 -> 705.22095 | I11: =H63-F63 -> 29.937757 | J11: =H11+K11 -> 734.10386 | K11: =J63-H63 -> 28.882906 | L11: =J11+M11 -> 787.93872 | M11: =L63-J63 -> 53.834857 | N11: =L11+O11 -> 853.474 | O11: =N63-L63 -> 65.535284 | P11: =N11+Q11 -> 882.09361 | Q11: =P63-N63 -> 28.619609
B12: （二）非息净收入 | C12: 92.51137 | D12: 103.89092 | E12: =D12-C12 -> 11.379549 | F12: 110.84027 | G12: =F12-D12 -> 6.949351 | H12: =F12+I12 -> 114.44131 | I12: =中收测算表!$L9-中收测算表!$L8 -> 3.6010382 | J12: =H12+K12 -> 117.33463 | K12: =中收测算表!$L10-中收测算表!$L9 -> 2.8933207 | L12: =J12+M12 -> 120.46837 | M12: =中收测算表!$L11-中收测算表!$L10 -> 3.1337446 | N12: =L12+O12 -> 123.85785 | O12: =中收测算表!$L12-中收测算表!$L11 -> 3.3894812 | P12: =N12+Q12 -> 127.5195 | Q12: =中收测算表!$L13-中收测算表!$L12 -> 3.6616407
B13: 二、营业支出 | C13: 286.66983 | D13: 292.99939 | E13: =D13-C13 -> 6.329559 | F13: 384.30306 | G13: =F13-D13 -> 91.303671 | H13: =H15+H16+H14 -> 399.30229 | I13: =H13-F13 -> 14.999232 | J13: =J15+J16+J14 -> 411.58885 | K13: =J13-H13 -> 12.286557 | L13: =L15+L16+L14 -> 419.7797 | M13: =L13-J13 -> 8.1908535 | N13: =N15+N16+N14 -> 484.77724 | O13: =N13-L13 -> 64.997539 | P13: =P15+P16+P14 -> 553.86014 | Q13: =P13-N13 -> 69.082897
B14: （一）税金及附加 | C14: 8.683676 | D14: 9.098435 | E14: =D14-C14 -> 0.414759 | F14: 8.687011 | G14: =F14-D14 -> -0.411424 | H14: =F14 -> 8.687011 | I14: 0 | J14: =H14 -> 8.687011 | K14: 0 | L14: =J14 -> 8.687011 | M14: 0 | N14: =L14 -> 8.687011 | O14: 0 | P14: =N14 -> 8.687011 | Q14: 0
B15: （二）营业费用 | C15: 177.66118 | D15: 180.12733 | E15: =D15-C15 -> 2.466141 | F15: 175.07805 | G15: =F15-D15 -> -5.049275 | H15: =F15+I15 -> 182.85053 | I15: =I93 -> 7.7724776 | J15: =H15+K15 -> 188.15812 | K15: =K93 -> 5.3075895 | L15: =J15+M15 -> 196.32865 | M15: =M93 -> 8.1705297 | N15: =L15+O15 -> 205.17385 | O15: =O93 -> 8.8452024 | P15: =N15+Q15 -> 212.7441 | Q15: =Q93 -> 7.5702501
B16: （三）资产减值损失 | C16: 100.32497 | D16: 103.77363 | E16: =D16-C16 -> 3.448659 | F16: 200.538 | G16: =F16-D16 -> 96.76437 | H16: =F16+I16 -> 207.76475 | I16: =I99 -> 7.2267546 | J16: =H16+K16 -> 214.74372 | K16: =K99 -> 6.9789675 | L16: =J16+M16 -> 214.76404 | M16: =M99 -> 0.020323858 | N16: =L16+O16 -> 270.91638 | O16: =O99 -> 56.152336 | P16: =N16+Q16 -> 332.42903 | Q16: =Q99 -> 61.512647
B17: 三、所得税费用 | C17: 117.33914 | D17: 116.76586 | E17: =D17-C17 -> -0.573283 | F17: 100.75284 | G17: =F17-D17 -> -16.013012 | H17: =F17+I17 -> 103.75284 | I17: =I106 -> 3 | J17: =H17+K17 -> 107.87071 | K17: =K106 -> 4.1178628 | L17: =J17+M17 -> 114.11108 | M17: =M106 -> 6.2403762 | N17: =L17+O17 -> 120.86925 | O17: =O106 -> 6.7581669 | P17: =N17+Q17 -> 126.70663 | Q17: =Q106 -> 5.8373749
B18: 四、净利润 | C18: =350.8461+0.06 -> 350.9061 | D18: 349.12253 | E18: =D18-C18 -> -1.783571 | F18: 301.05028 | G18: =F18-D18 -> -48.072252 | H18: =H10-H13-H17 -> 316.60713 | I18: =H18-F18 -> 15.556849 | J18: =J10-J13-J17 -> 331.97893 | K18: =J18-H18 -> 15.371807 | L18: =L10-L13-L17 -> 374.5163 | M18: =L18-J18 -> 42.537372 | N18: =N10-N13-N17 -> 371.68536 | O18: =N18-L18 -> -2.8309401 | P18: =P10-P13-P17 -> 329.04634 | Q18: =P18-N18 -> -42.639023
B19: 五、资本占用 | C19: 3209 | D19: 3546 | E19: =D19-C19 -> 337 | F19: 3954 | G19: =F19-D19 -> 408 | H19: =F19+I19 -> 4287.8531 | I19: =SUMIF(资本!$AG:$AG,"对公",资本!G:G)*0.11 -> 333.8531 | J19: =H19+K19 -> 4582.3015 | K19: =SUMIF(资本!$AG:$AG,"对公",资本!K:K)*0.11 -> 294.44836 | L19: =J19+M19 -> 4861.8967 | M19: =SUMIF(资本!$AG:$AG,"对公",资本!O:O)*0.11 -> 279.59527 | N19: =L19+O19 -> 5104.5699 | O19: =SUMIF(资本!$AG:$AG,"对公",资本!S:S)*0.11 -> 242.6732 | P19: =N19+Q19 -> 5342.8198 | Q19: =SUMIF(资本!$AG:$AG,"对公",资本!W:W)*0.11 -> 238.24988
B20: 六、成本收入比 | C20: 0.2353 | D20: 0.2373 | E20: =D20-C20 -> 0.002 | F20: 0.2227 | G20: =F20-D20 -> -0.0146 | H20: =H15/H10 -> 0.22308033 | I20: =H20-F20 -> 0.00038032944 | J20: =J15/J10 -> 0.2209885 | K20: =J20-H20 -> -0.0020918265 | L20: =L15/L10 -> 0.21612408 | M20: =L20-J20 -> -0.004864423 | N20: =N15/N10 -> 0.20993263 | O20: =N20-L20 -> -0.0061914478 | P20: =P15/P10 -> 0.21071844 | Q20: =P20-N20 -> 0.00078580841
B21: 七、风险成本率 | C21: =C16/C10 -> 0.13288955 | D21: =D16/D10 -> 0.13673961 | E21: =D21-C21 -> 0.003850067 | F21: =F16/F10 -> 0.25509733 | G21: =F21-D21 -> 0.11835772 | H21: =H16/H10 -> 0.25347605 | I21: =H21-F21 -> -0.0016212809 | J21: =J16/J10 -> 0.25221284 | K21: =J21-H21 -> -0.0012632092 | L21: =L16/L10 -> 0.23641828 | M21: =L21-J21 -> -0.015794559 | N21: =N16/N10 -> 0.27719999 | O21: =N21-L21 -> 0.040781707 | P21: =P16/P10 -> 0.32926378 | Q21: =P21-N21 -> 0.05206379
B22: 八、税务成本率 | C22: =(C17+C14)/C10 -> 0.16692868 | D22: =(D17+D14)/D10 -> 0.16584786 | E22: =D22-C22 -> -0.0010808172 | F22: =(F17+F14)/F10 -> 0.13921459 | G22: =F22-D22 -> -0.026633272 | H22: =(H17+H14)/H10 -> 0.13717828 | I22: =H22-F22 -> -0.0020363139 | J22: =(J17+J14)/J10 -> 0.13689505 | K22: =J22-H22 -> -0.00028322095 | L22: =(L17+L14)/L10 -> 0.13517959 | M22: =L22-J22 -> -0.0017154684 | N22: =(N17+N14)/N10 -> 0.13256118 | O22: =N22-L22 -> -0.0026184089 | P22: =(P17+P14)/P10 -> 0.13410448 | Q22: =P22-N22 -> 0.0015432986
B23: 九、营收/风险资产 | C23: =C10/C19*0.11 -> 0.025878625 | D23: =D10/D19*0.11 -> 0.023542177 | E23: =D23-C23 -> -0.002336448 | F23: =F10/F19*0.11 -> 0.021869899 | G23: =F23-D23 -> -0.0016722775 | H23: =H10/H19*0.11 -> 0.021027504 | I23: =H23-F23 -> -0.00084239502 | J23: =J10/J19*0.11 -> 0.020439125 | K23: =J23-H23 -> -0.00058837881 | L23: =L10/L19*0.11 -> 0.020552633 | M23: =L23-J23 -> 0.00011350784 | N23: =N10/N19*0.11 -> 0.021060835 | O23: =N23-L23 -> 0.00050820166 | P23: =P10/P19*0.11 -> 0.020786297 | Q23: =P23-N23 -> -0.00027453743
B24: 十、风险资本回报率 | C24: =C18/C19 -> 0.10935061 | D24: =D18/D19 -> 0.09845531 | E24: =D24-C24 -> -0.010895298 | F24: =F18/F19 -> 0.076138158 | G24: =F24-D24 -> -0.022317152 | H24: =H18/H19 -> 0.073838147 | I24: =H24-F24 -> -0.0023000115 | J24: =J18/J19 -> 0.072448078 | K24: =J24-H24 -> -0.0013900687 | L24: =L18/L19 -> 0.077030905 | M24: =L24-J24 -> 0.0045828271 | N24: =N18/N19 -> 0.072814237 | O24: =N24-L24 -> -0.0042166679 | P24: =P18/P19 -> 0.061586644 | Q24: =P24-N24 -> -0.011227593
A25: 零售板块 | B25: 零售板块占全行营收比 | C25: =C27/'2026-2030年盈利测算表'!$H$12 -> 0.40165903 | D25: =D27/'2026-2030年盈利测算表'!$J$12 -> 0.36305681 | E25: =D25-C25 -> -0.038602219 | F25: =F27/'2026-2030年盈利测算表'!$L$12 -> 0.34547735 | G25: =F25-D25 -> -0.017579463 | H25: =H27/S$4 -> 0.33564503 | I25: =H25-F25 -> -0.0098323239 | J25: =J27/U$4 -> 0.32719425 | K25: =J25-H25 -> -0.0084507792 | L25: =L27/W$4 -> 0.3231747 | M25: =L25-J25 -> -0.0040195476 | N25: =N27/Y$4 -> 0.3252341 | O25: =N25-L25 -> 0.0020594047 | P25: =P27/AA$4 -> 0.32218231 | Q25: =P25-N25 -> -0.0030517991
B26: 零售板块占全行净利润比 | C26: =C35/'2026-2030年盈利测算表'!$H$11 -> 0.043708258 | D26: =D35/'2026-2030年盈利测算表'!$J$11 -> 0.0024893781 | E26: =D26-C26 -> -0.04121888 | F26: =F35/'2026-2030年盈利测算表'!$L$11 -> -0.023901804 | G26: =F26-D26 -> -0.026391182 | H26: =H35/S$7 -> -0.035034426 | I26: =H26-F26 -> -0.011132622 | J26: =J35/U$7 -> -0.039557975 | K26: =J26-H26 -> -0.004523549 | L26: =L35/W$7 -> -0.040667202 | M26: =L26-J26 -> -0.0011092274 | N26: =N35/Y$7 -> 0.039372332 | O26: =N26-L26 -> 0.080039534 | P26: =P35/AA$7 -> 0.10377724 | Q26: =P26-N26 -> 0.064404908
B27: 一、营业净收入 | C27: 767.97207 | D27: 727.2028 | E27: =D27-C27 -> -40.769272 | F27: 670.79264 | G27: =F27-D27 -> -56.410154 | H27: =H28+H29 -> 680.63369 | I27: =I28+I29 -> 9.8410499 | J27: =J28+J29 -> 683.84144 | K27: =K28+K29 -> 3.207747 | L27: =L28+L29 -> 705.89273 | M27: =M28+M29 -> 22.05129 | N27: =N28+N29 -> 743.58009 | O27: =O28+O29 -> 37.687362 | ... Q27: =Q28+Q29 -> 21.420842
B28: （一）利息净收入 | C28: 538.44495 | D28: 520.03316 | E28: =D28-C28 -> -18.411786 | F28: 478.69 | G28: =F28-D28 -> -41.34316 | H28: =F28+I28 -> 480.94973 | I28: =H64-F64 -> 2.2597287 | J28: =H28+K28 -> 477.26932 | K28: =J64-H64 -> -3.6804068 | L28: =J28+M28 -> 489.66674 | M28: =L64-J64 -> 12.397415 | N28: =L28+O28 -> 512.61919 | O28: =N64-L64 -> 22.952455 | P28: =N28+Q28 -> 519.45248 | Q28: =P64-N64 -> 6.8332843
B29: （二）非息净收入 | C29: 229.52712 | D29: 207.16964 | E29: =D29-C29 -> -22.357487 | F29: 192.10264 | G29: =F29-D29 -> -15.066993 | H29: =F29+I29 -> 199.68396 | I29: =中收测算表!$J9-中收测算表!$J8+中收测算表!$N9-中收测算表!$N8 -> 7.5813212 | J29: =H29+K29 -> 206.57212 | K29: =中收测算表!$J10-中收测算表!$J9+中收测算表!$N10-中收测算表!$N9 -> 6.8881538 | L29: =J29+M29 -> 216.22599 | M29: =中收测算表!$J11-中收测算表!$J10+中收测算表!$N11-中收测算表!$N10 -> 9.6538752 | N29: =L29+O29 -> 230.9609 | O29: =中收测算表!$J12-中收测算表!$J11+中收测算表!$N12-中收测算表!$N11 -> 14.734907 | P29: =N29+Q29 -> 245.54846 | Q29: =中收测算表!$J13-中收测算表!$J12+中收测算表!$N13-中收测算表!$N12 -> 14.587558
B30: 二、营业支出 | C30: 731.22019 | D30: 724.6131 | E30: =D30-C30 -> -6.60709 | F30: 685.65282 | G30: =F30-D30 -> -38.960276 | H30: =H32+H33+H31 -> 704.00466 | I30: =H30-F30 -> 18.351833 | J30: =J32+J33+J31 -> 711.60164 | K30: =J30-H30 -> 7.596979 | L30: =L32+L33+L31 -> 736.25551 | M30: =L30-J30 -> 24.653875 | N30: =N32+N33+N31 -> 710.99042 | O30: =N30-L30 -> -25.265093 | P30: =P32+P33+P31 -> 675.57798 | Q30: =P30-N30 -> -35.412442
B31: （一）税金及附加 | C31: 9.39503 | D31: 8.992212 | E31: =D31-C31 -> -0.402818 | F31: 7.984384 | G31: =F31-D31 -> -1.007828 | H31: =F31+I31 -> 7.984384 | I31: =I107 -> 0 | J31: =H31+K31 -> 7.984384 | K31: =K107 -> 0 | L31: =J31+M31 -> 7.984384 | M31: =M107 -> 0 | N31: =L31+O31 -> 7.984384 | O31: =O107 -> 0 | P31: =N31+Q31 -> 7.984384 | Q31: =Q107 -> 0
B32: （二）营业费用 | C32: 268.45312 | D32: 267.89367 | E32: =D32-C32 -> -0.55945 | F32: 250.59667 | G32: =F32-D32 -> -17.297 | H32: =F32+I32 -> 261.72175 | I32: =I94 -> 11.125078 | J32: =H32+K32 -> 269.31873 | K32: =K94 -> 7.596979 | L32: =J32+M32 -> 278.9726 | M32: =M88 -> 9.6538752 | N32: =L32+O32 -> 293.70751 | O32: =O88 -> 14.734907 | P32: =N32+Q32 -> 308.29507 | Q32: =Q88 -> 14.587558
B33: （三）资产减值损失 | C33: 453.37204 | D33: 447.72722 | E33: =D33-C33 -> -5.644823 | F33: 427.07177 | G33: =F33-D33 -> -20.655448 | H33: =F33+I33 -> 434.29852 | I33: =I100 -> 7.2267546 | J33: =H33+K33 -> 434.29852 | K33: =K100 -> 0 | L33: =J33+M33 -> 449.29852 | M33: =M100 -> 15 | N33: =L33+O33 -> 409.29852 | O33: =O100 -> -40 | P33: =N33+Q33 -> 359.29852 | Q33: =Q100 -> -50
B34: 三、所得税费用 | C34: 9.375067 | D34: 0.91358 | E34: =D34-C34 -> -8.461487 | F34: 0.658195 | G34: =F34-D34 -> -0.255385 | H34: =F34+I31 -> 0.658195 | I34: 0 | J34: =H34+K34 -> 0.658195 | K34: 0 | L34: =J34+M34 -> 0.658195 | M34: 0 | N34: =L34+O34 -> 0.658195 | O34: 0 | P34: =N34+Q34 -> 0.658195 | Q34: 0
B35: 四、净利润 | C35: 27.383661 | D35: =1.60225+0.05 -> 1.65225 | E35: =D35-C35 -> -25.731411 | F35: =-15.414706-0.05 -> -15.464706 | G35: =F35-D35 -> -17.116956 | H35: =H27-H30-H34 -> -24.029159 | I35: =H35-F35 -> -8.564453 | J35: =J27-J30-J34 -> -28.418391 | K35: =J35-H35 -> -4.3892321 | L35: =L27-L30-L34 -> -31.020976 | M35: =L35-J35 -> -2.6025854 | N35: =N27-N30-N34 -> 31.931478 | O35: =N35-L35 -> 62.952455 | P35: =P27-P30-P34 -> 88.764763 | Q35: =P35-N35 -> 56.833284
B36: 五、资本占用 | C36: 1668 | D36: 1433.45 | E36: =D36-C36 -> -234.55 | F36: 1435 | G36: =F36-D36 -> 1.55 | H36: =F36+I36 -> 1412.3045 | I36: =SUMIF(资本!$AG:$AG,"零售",资本!G:G)*0.11 -> -22.6955 | J36: =H36+K36 -> 1403.6448 | K36: =SUMIF(资本!$AG:$AG,"零售",资本!K:K)*0.11 -> -8.659651 | L36: =J36+M36 -> 1406.8732 | M36: =SUMIF(资本!$AG:$AG,"零售",资本!O:O)*0.11 -> 3.2283343 | N36: =L36+O36 -> 1410.1205 | O36: =SUMIF(资本!$AG:$AG,"零售",资本!S:S)*0.11 -> 3.2473219 | P36: =N36+Q36 -> 1413.3866 | Q36: =SUMIF(资本!$AG:$AG,"零售",资本!W:W)*0.11 -> 3.2660576
B37: 六、成本收入比 | C37: 0.3496 | D37: 0.3684 | E37: =D37-C37 -> 0.0188 | F37: 0.3736 | G37: =F37-D37 -> 0.0052 | H37: =H32/H27 -> 0.38452659 | I37: =H37-F37 -> 0.010926586 | J37: =J32/J27 -> 0.39383213 | K37: =J37-H37 -> 0.0093055417 | L37: =L32/L27 -> 0.39520538 | M37: =L37-J37 -> 0.0013732524 | N37: =N32/N27 -> 0.39499109 | O37: =N37-L37 -> -0.00021428916 | P37: =P32/P27 -> 0.4029996 | Q37: =P37-N37 -> 0.008008508
B38: 七、风险成本率 | C38: =C33/C27 -> 0.59034965 | D38: =D33/D27 -> 0.61568412 | E38: =D38-C38 -> 0.025334477 | F38: =F33/F27 -> 0.63666734 | G38: =F38-D38 -> 0.020983218 | H38: =H33/H27 -> 0.63807967 | I38: =H38-F38 -> 0.0014123302 | J38: =J33/J27 -> 0.63508658 | K38: =J38-H38 -> -0.0029930887 | L38: =L33/L27 -> 0.63649688 | M38: =L38-J38 -> 0.0014103017 | N38: =N33/N27 -> 0.55044309 | O38: =N38-L38 -> -0.086053794 | P38: =P33/P27 -> 0.4696707 | Q38: =P38-N38 -> -0.080772391
B39: 八、税务成本率 | C39: =(C34+C31)/C27 -> 0.024441119 | D39: =(D34+D31)/D27 -> 0.013621774 | E39: =D39-C39 -> -0.010819346 | F39: =(F34+F31)/F27 -> 0.012884129 | G39: =F39-D39 -> -0.00073764471 | H39: =(H34+H31)/H27 -> 0.012697842 | I39: =H39-F39 -> -0.00018628722 | J39: =(J34+J31)/J27 -> 0.012638279 | K39: =J39-H39 -> -5.9562731e-05 | L39: =(L34+L31)/L27 -> 0.012243474 | M39: =L39-J39 -> -0.00039480553 | N39: =(N34+N31)/N27 -> 0.01162293 | O39: =N39-L39 -> -0.00062054407 | P39: =(P34+P31)/P27 -> 0.011297475 | Q39: =P39-N39 -> -0.00032545442
